#VRML_SIM R2023b utf8

EXTERNPROTO "https://raw.githubusercontent.com/cyberbotics/webots/R2023b/projects/appearances/protos/OsbWood.proto"
EXTERNPROTO "https://raw.githubusercontent.com/cyberbotics/webots/R2023b/projects/objects/floors/protos/RectangleArena.proto"
EXTERNPROTO "https://raw.githubusercontent.com/cyberbotics/webots/R2023b/projects/objects/backgrounds/protos/TexturedBackground.proto"
EXTERNPROTO "https://raw.githubusercontent.com/cyberbotics/webots/R2023b/projects/objects/backgrounds/protos/TexturedBackgroundLight.proto"

WorldInfo {
  info [
    "In this example, the robot turns on a slope."
    "Its accelerometer sensor is used to switch on the bottommost LED."
  ]
  title "Accelerometer"
  basicTimeStep 8
  contactProperties [
    ContactProperties {
      material2 "body"
      coulombFriction [
        0
      ]
      softCFM 0.1
    }
  ]
}
Viewpoint {
  orientation -0.22269325832374712 0.010955926484435358 0.9748270002272302 3.1750748986819244
  position 0.787772570873493 0.11730341209474196 0.5920735854488881
}
TexturedBackground {
}
TexturedBackgroundLight {
}
RectangleArena {
}
PointLight {
  attenuation 0 0 1
  intensity 0.6
  location 0.6 0 0
}
DEF SLOPE Solid {
  translation 0 0 0.15
  rotation 1 0 0 -1.970795
  children [
    Shape {
      appearance OsbWood {
        textureTransform TextureTransform {
          scale 0.5 2
        }
      }
      geometry DEF BOX0 Box {
        size 0.2 0.02 0.8
      }
    }
  ]
  name "green box"
  boundingObject USE BOX0
}
Robot {
  translation 7.310591402267266e-06 0.048767285405146396 0.1403438912004923
  rotation -0.23876502396146623 0.23872417579964497 0.9412768090319982 1.6310605099890363
  children [
    Accelerometer {
    }
    Pose {
      translation 0 0 0.0415
      children [
        Shape {
          appearance PBRAppearance {
            baseColor 0.0820075 0.364731 0.8
            roughness 1
            metalness 0
          }
          geometry DEF BODY Cylinder {
            height 0.08
            radius 0.045
          }
        }
      ]
    }
    HingeJoint {
      jointParameters HingeJointParameters {
        position 2.8619832924736905e-08
        axis 0 1 0
        anchor 0 0 0.025
      }
      device [
        RotationalMotor {
          name "left wheel motor"
          consumptionFactor 70
        }
        PositionSensor {
          name "left wheel sensor"
        }
      ]
      endPoint Solid {
        translation 0 0.04499999999999997 0.025
        rotation 0.5773502636817366 -0.5773502636817354 -0.577350280205405 2.094394983476332
        children [
          DEF WHEEL Pose {
            rotation 0.577656895078166 0.5771968951617173 -0.5771968951617173 -2.093935
            children [
              Shape {
                appearance PBRAppearance {
                  baseColor 1 0 0
                  roughness 1
                  metalness 0
                }
                geometry Cylinder {
                  height 0.01
                  radius 0.025
                }
              }
            ]
          }
        ]
        name "left wheel"
        boundingObject USE WHEEL
        physics DEF PHYSICS_WHEEL Physics {
          density -1
          mass 0.05
        }
        linearVelocity -1.2564435877439239e-12 5.276269083207736e-06 -2.2307531769704874e-06
        angularVelocity -2.7692657203618596e-08 6.381011772914146e-09 1.5163865888241725e-08
      }
    }
    HingeJoint {
      jointParameters HingeJointParameters {
        position 4.3121113364346496e-08
        axis 0 1 0
        anchor 0 0 0.025
      }
      device [
        RotationalMotor {
          name "right wheel motor"
          consumptionFactor 70
        }
        PositionSensor {
          name "right wheel sensor"
        }
      ]
      endPoint Solid {
        translation 0 -0.04499999999999996 0.025
        rotation 0.577350260890964 -0.5773502608909625 -0.5773502857869505 2.094394975104014
        children [
          USE WHEEL
        ]
        boundingObject USE WHEEL
        physics USE PHYSICS_WHEEL
        linearVelocity -9.599480431414076e-13 5.277540961756677e-06 -2.2312876892890875e-06
        angularVelocity 1.1745012347213239e-07 6.352876814408207e-09 1.5177240131278025e-08
      }
    }
    DistanceSensor {
      translation 0.042 0.02 0.063
      rotation 0 0 -1 -0.499205
      children [
        DEF SENSOR Pose {
          rotation 0.577656895078166 0.5771968951617173 -0.5771968951617173 -2.093935
          children [
            Shape {
              appearance PBRAppearance {
                baseColor 0.975691 0.981481 0.0252992
                roughness 1
                metalness 0
              }
              geometry Cylinder {
                height 0.004
                radius 0.008
              }
            }
          ]
        }
      ]
      name "ds0"
      lookupTable [
        0 1024 0
        0.05 1024 0
        0.15 0 0
      ]
      numberOfRays 2
      aperture 1
    }
    DistanceSensor {
      translation 0.042 -0.02 0.063
      rotation 0 0 1 -0.500795
      children [
        USE SENSOR
      ]
      name "ds1"
      lookupTable [
        0 1024 0
        0.05 1024 0
        0.15 0 0
      ]
      numberOfRays 2
      aperture 1
    }
    DEF SMILE Pose {
      translation 0.036 0 0.025
      rotation 0 0 1 -0.5007953071795859
      children [
        Shape {
          appearance PBRAppearance {
            baseColor 0.721569 0.290196 0.290196
            roughness 1
            metalness 0
          }
          geometry Cylinder {
            height 0.018
            radius 0.009
            subdivision 3
          }
        }
      ]
    }
  ]
  name "MyBot"
  contactMaterial "body"
  boundingObject Pose {
    translation 0 0 0.0415
    rotation 0 0 1 -1.570796
    children [
      USE BODY
    ]
  }
  physics Physics {
    density -1
    mass 0.5
  }
  controller "python_controller"
  linearVelocity -2.7845350312479888e-11 5.2773046468465175e-06 -2.2312367611758053e-06
  angularVelocity -2.7501492764605333e-08 6.380990689623242e-09 1.516389982330473e-08
}
